Workbook

Sheet RCG INTERS 
A1: DATE | B1: NET MTM | C1: RUNNING P&l | D1: TAX COST | E1: TAX RUNNING COST | F1: INTREST COST 5% P.A 36 L | G1: POSITION CR/DR | H1: % OF CR/DR VS MARGIN | I1: RUNNING ROI ON DEPOSITE | J1: RUNNING ROI ON COMPOUNDING | K1: DYA ROI ON DEPOSITE | L1: COMPOUNDED ROI | M1: RETURN ON USE MARGIN | N1: MARGIN USE CARRY | O1: CARRY +PEAK | P1: AVG DEPOSITE | Q1: NET MARGIN | R1: RUNNING BALANCE | S1: RUNNING RETURN ON NET MARGIN | T1: DYA RETURN ON NET MARGIN
A2: 46146 | B2: 1238 | C2: 1238 | D2: 660 | E2: 660 | F2: 493 | G2: =IFERROR(VLOOKUP(A2,[1]SUMMERY!$A$2:$G$21,7,FALSE),"") -> 159211 | H2: =G2*100/N2 -> 20.310582 | I2: =(C2-SUM($F$2:F2))*100/P2 -> 0.057707204 | J2: =(C2-SUM($F$2:F2))*100/Q2 -> 0.015520833 | K2: =(B2-F2)*100/P2 -> 0.057707204 | L2: =C2*100/P2 -> 0.095894655 | M2: =B2*100/O2 -> 0.1258281 | N2: 783882 | O2: =N2+200000 -> 983882 | P2: 1291000 | Q2: 4800000 | R2: =P2+C2 -> 1292238 | S2: =C2*100/Q2 -> 0.025791667 | T2: =B2*100/Q2 -> 0.025791667
A3: =WORKDAY(A2,1) -> 46147 | B3: =IFERROR(IF(C3<>C2,C3-C2,""),"") -> 23246 | C3: 24484 | D3: =IF(OR(E2="",E3=""),"",E3-E2) -> 469 | E3: 1129 | F3: 493 | G3: =IFERROR(VLOOKUP(A3,[1]SUMMERY!$A$2:$G$21,7,FALSE),"") -> 287599 | H3: =G3*100/N3 -> 19.7403 | I3: =(C3-SUM($F$2:F3))*100/P3 -> 1.8201394 | J3: =(C3-SUM($F$2:F3))*100/Q3 -> 0.48954167 | K3: =(B3-F3)*100/P3 -> 1.7624322 | L3: =(C3-SUM($F$2:F3))*100/P3 -> 1.8201394 | M3: =B3*100/O3 -> 1.4029705 | N3: 1456913 | O3: =N3+200000 -> 1656913 | P3: 1291000 | Q3: 4800000 | R3: =P3+C3 -> 1315484 | S3: =C3*100/Q3 -> 0.51008333 | T3: =B3*100/Q3 -> 0.48429167
A4: =WORKDAY(A3,1) -> 46148 | B4: =IFERROR(IF(C4<>C3,C4-C3,""),"") -> -13730 | C4: 10754 | D4: =IF(OR(E3="",E4=""),"",E4-E3) -> 886 | E4: 2015 | F4: 493 | G4: =IFERROR(VLOOKUP(A4,[1]SUMMERY!$A$2:$G$21,7,FALSE),"") -> 467070.5 | H4: =G4*100/N4 -> 24.989046 | I4: =(C4-SUM($F$2:F4))*100/P4 -> 0.71843532 | J4: =(C4-SUM($F$2:F4))*100/Q4 -> 0.19322917 | K4: =(B4-F4)*100/P4 -> -1.1017041 | L4: =(C4-SUM($F$2:F4))*100/P4 -> 0.71843532 | M4: =B4*100/O4 -> -0.66357321 | N4: 1869101 | O4: =N4+200000 -> 2069101 | P4: 1291000 | Q4: 4800000 | R4: =P4+C4 -> 1301754 | S4: =C4*100/Q4 -> 0.22404167 | T4: =B4*100/Q4 -> -0.28604167
A5: =WORKDAY(A4,1) -> 46149 | B5: =IFERROR(IF(C5<>C4,C5-C4,""),"") -> 45363 | C5: 56117 | D5: =IF(OR(E4="",E5=""),"",E5-E4) -> 901 | E5: 2916 | F5: 493 | G5: =IFERROR(VLOOKUP(A5,[1]SUMMERY!$A$2:$G$21,7,FALSE),"") -> 482761.5 | H5: =G5*100/N5 -> 21.571199 | I5: =(C5-SUM($F$2:F5))*100/P5 -> 4.1940356 | J5: =(C5-SUM($F$2:F5))*100/Q5 -> 1.1280208 | K5: =(B5-F5)*100/P5 -> 3.4756003 | L5: =(C5-SUM($F$2:F5))*100/P5 -> 4.1940356 | M5: =B5*100/O5 -> 1.8606713 | N5: 2237991 | O5: =N5+200000 -> 2437991 | P5: 1291000 | Q5: 4800000 | R5: =P5+C5 -> 1347117 | S5: =C5*100/Q5 -> 1.1691042 | T5: =B5*100/Q5 -> 0.9450625
A6: =WORKDAY(A5,1) -> 46150 | B6: =IFERROR(IF(C6<>C5,C6-C5,""),"") -> 17156 | C6: 73273 | D6: =IF(OR(E5="",E6=""),"",E6-E5) -> 397 | E6: 3313 | F6: 493 | G6: =IFERROR(VLOOKUP(A6,[1]SUMMERY!$A$2:$G$21,7,FALSE),"") -> 399363.25 | H6: =G6*100/N6 -> 21.498407 | I6: =(C6-SUM($F$2:F6))*100/P6 -> 5.4847405 | J6: =(C6-SUM($F$2:F6))*100/Q6 -> 1.4751667 | K6: =(B6-F6)*100/P6 -> 1.2907049 | L6: =(C6-SUM($F$2:F6))*100/P6 -> 5.4847405 | M6: =B6*100/O6 -> 0.83377026 | N6: 1857641.2 | O6: =N6+200000 -> 2057641.2 | P6: 1291000 | Q6: 4800000 | R6: =P6+C6 -> 1364273 | S6: =C6*100/Q6 -> 1.5265208 | T6: =B6*100/Q6 -> 0.35741667
A7: =WORKDAY(A6,1) -> 46153 | B7: =IFERROR(IF(C7<>C6,C7-C6,""),"") -> -63606 | C7: 9667 | D7: =IF(OR(E6="",E7=""),"",E7-E6) -> 1088 | E7: 4401 | F7: 493 | G7: =IFERROR(VLOOKUP(A7,[1]SUMMERY!$A$2:$G$21,7,FALSE),"") -> 620246.25 | H7: =G7*100/N7 -> 21.033589 | I7: =(C7-SUM($F$2:F7))*100/P7 -> 0.51967467 | J7: =(C7-SUM($F$2:F7))*100/Q7 -> 0.13977083 | K7: =(B7-F7)*100/P7 -> -4.9650658 | L7: =(C7-SUM($F$2:F7))*100/P7 -> 0.51967467 | M7: =B7*100/O7 -> -2.0199839 | N7: 2948837 | O7: =N7+200000 -> 3148837 | P7: 1291000 | Q7: 4800000 | R7: =P7+C7 -> 1300667 | S7: =C7*100/Q7 -> 0.20139583 | T7: =B7*100/Q7 -> -1.325125
A8: =WORKDAY(A7,1) -> 46154 | B8: =IFERROR(IF(C8<>C7,C8-C7,""),"") -> -214994 | C8: -205327 | D8: =IF(OR(E7="",E8=""),"",E8-E7) -> 1346 | E8: 5747 | F8: 493 | G8: =IFERROR(VLOOKUP(A8,[1]SUMMERY!$A$2:$G$21,7,FALSE),"") -> 757120 | H8: =G8*100/N8 -> 42.022954 | I8: =(C8-SUM($F$2:F8))*100/P8 -> -16.171805 | J8: =(C8-SUM($F$2:F8))*100/Q8 -> -4.3495417 | K8: =(B8-F8)*100/P8 -> -16.691479 | L8: =(C8-SUM($F$2:F8))*100/P8 -> -16.171805 | M8: =B8*100/O8 -> -10.740667 | N8: 1801682 | O8: =N8+200000 -> 2001682 | P8: 1291000 | Q8: 4800000 | R8: =P8+C8 -> 1085673 | S8: =C8*100/Q8 -> -4.2776458 | T8: =B8*100/Q8 -> -4.4790417
A9: =WORKDAY(A8,1) -> 46155 | B9: =IFERROR(IF(C9<>C8,C9-C8,""),"") -> 33360 | C9: -171967 | D9: =IF(OR(E8="",E9=""),"",E9-E8) -> 1733 | E9: 7480 | F9: 493 | G9: =IFERROR(VLOOKUP(A9,[1]SUMMERY!$A$2:$G$21,7,FALSE),"") -> 1065629.5 | H9: =G9*100/N9 -> 41.529353 | I9: =(C9-SUM($F$2:F9))*100/P9 -> -13.625949 | J9: =(C9-SUM($F$2:F9))*100/Q9 -> -3.6648125 | K9: =(B9-F9)*100/P9 -> 2.5458559 | L9: =(C9-SUM($F$2:F9))*100/P9 -> -13.625949 | M9: =B9*100/O9 -> 1.2060881 | N9: 2565967 | O9: =N9+200000 -> 2765967 | P9: 1291000 | Q9: 4800000 | R9: =P9+C9 -> 1119033 | S9: =C9*100/Q9 -> -3.5826458 | T9: =B9*100/Q9 -> 0.695
A10: =WORKDAY(A9,1) -> 46156 | B10: =IFERROR(IF(C10<>C9,C10-C9,""),"") -> 52179 | C10: -119788 | D10: =IF(OR(E9="",E10=""),"",E10-E9) -> 579 | E10: 8059 | F10: 493 | G10: =IFERROR(VLOOKUP(A10,[1]SUMMERY!$A$2:$G$21,7,FALSE),"") -> 840960.25 | H10: =G10*100/N10 -> 41.797811 | I10: =(C10-SUM($F$2:F10))*100/P10 -> -9.6223857 | J10: =(C10-SUM($F$2:F10))*100/Q10 -> -2.5880208 | K10: =(B10-F10)*100/P10 -> 4.0035631 | L10: =(C10-SUM($F$2:F10))*100/P10 -> -9.6223857 | M10: =B10*100/O10 -> 2.3589358 | N10: 2011972 | O10: =N10+200000 -> 2211972 | P10: 1291000 | Q10: 4800000 | R10: =P10+C10 -> 1171212 | S10: =C10*100/Q10 -> -2.4955833 | T10: =B10*100/Q10 -> 1.0870625
A11: =WORKDAY(A10,1) -> 46157 | B11: =IFERROR(IF(C11<>C10,C11-C10,""),"") -> 11488 | C11: -108300 | D11: =IF(OR(E10="",E11=""),"",E11-E10) -> 815 | E11: 8874 | F11: 493 | G11: =IFERROR(VLOOKUP(A11,[1]SUMMERY!$A$2:$G$21,7,FALSE),"") -> 1058924.8 | H11: =G11*100/N11 -> 37.067359 | I11: =(C11-SUM($F$2:F11))*100/P11 -> -8.7707204 | J11: =(C11-SUM($F$2:F11))*100/Q11 -> -2.3589583 | K11: =(B11-F11)*100/P11 -> 0.85166538 | L11: =(C11-SUM($F$2:F11))*100/P11 -> -8.7707204 | M11: =B11*100/O11 -> 0.37582301 | N11: 2856758 | O11: =N11+200000 -> 3056758 | P11: 1291000 | Q11: 4800000 | R11: =P11+C11 -> 1182700 | S11: =C11*100/Q11 -> -2.25625 | T11: =B11*100/Q11 -> 0.23933333
A12: =WORKDAY(A11,1) -> 46160 | B12: =IFERROR(IF(C12<>C11,C12-C11,""),"") -> 6831 | C12: -101469 | D12: =IF(OR(E11="",E12=""),"",E12-E11) -> 1034 | E12: 9908 | F12: 493 | G12: =IFERROR(VLOOKUP(A12,[1]SUMMERY!$A$2:$G$21,7,FALSE),"") -> 1180946 | H12: =G12*100/N12 -> 42.998513 | I12: =(C12-SUM($F$2:F12))*100/P12 -> -8.2797831 | J12: =(C12-SUM($F$2:F12))*100/Q12 -> -2.2269167 | K12: =(B12-F12)*100/P12 -> 0.49093726 | L12: =(C12-SUM($F$2:F12))*100/P12 -> -8.2797831 | M12: =B12*100/O12 -> 0.23183587 | N12: 2746481 | O12: =N12+200000 -> 2946481 | P12: 1291000 | Q12: 4800000 | R12: =P12+C12 -> 1189531 | S12: =C12*100/Q12 -> -2.1139375 | T12: =B12*100/Q12 -> 0.1423125
A13: =WORKDAY(A12,1) -> 46161 | B13: =IFERROR(IF(C13<>C12,C13-C12,""),"") -> 41328 | C13: -60141 | D13: =IF(OR(E12="",E13=""),"",E13-E12) -> 870 | E13: 10778 | F13: 493 | G13: =IFERROR(VLOOKUP(A13,[1]SUMMERY!$A$2:$G$21,7,FALSE),"") -> 798476.25 | H13: =G13*100/N13 -> 44.035422 | I13: =(C13-SUM($F$2:F13))*100/P13 -> -5.1167312 | J13: =(C13-SUM($F$2:F13))*100/Q13 -> -1.3761875 | K13: =(B13-F13)*100/P13 -> 3.1630519 | L13: =(C13-SUM($F$2:F13))*100/P13 -> -5.1167312 | M13: =B13*100/O13 -> 2.052791 | N13: 1813259 | O13: =N13+200000 -> 2013259 | P13: 1291000 | Q13: 4800000 | R13: =P13+C13 -> 1230859 | S13: =C13*100/Q13 -> -1.2529375 | T13: =B13*100/Q13 -> 0.861
A14: =WORKDAY(A13,1) -> 46162 | B14: =IFERROR(IF(C14<>C13,C14-C13,""),"") -> 24067 | C14: -36074 | D14: =IF(OR(E13="",E14=""),"",E14-E13) -> 761 | E14: 11539 | F14: 493 | G14: =IFERROR(VLOOKUP(A14,[1]SUMMERY!$A$2:$G$21,7,FALSE),"") -> 747942 | H14: =G14*100/N14 -> 41.744381 | I14: =(C14-SUM($F$2:F14))*100/P14 -> -3.2907049 | J14: =(C14-SUM($F$2:F14))*100/Q14 -> -0.8850625 | K14: =(B14-F14)*100/P14 -> 1.8260263 | L14: =(C14-SUM($F$2:F14))*100/P14 -> -3.2907049 | M14: =B14*100/O14 -> 1.2083532 | N14: 1791719 | O14: =N14+200000 -> 1991719 | P14: 1291000 | Q14: 4800000 | R14: =P14+C14 -> 1254926 | S14: =C14*100/Q14 -> -0.75154167 | T14: =B14*100/Q14 -> 0.50139583
... A18: =WORKDAY(A17,1) -> 46168 | B18: =IFERROR(IF(C18<>C17,C18-C17,""),"") -> 35563 | C18: 67131 | D18: =IF(OR(E17="",E18=""),"",E18-E17) -> 486 | E18: 14339 | F18: 493 | G18: =IFERROR(VLOOKUP(A18,[1]SUMMERY!$A$2:$G$21,7,FALSE),"") -> 367237 | H18: =G18*100/N18 -> 43.212436 | I18: =(C18-SUM($F$2:F18))*100/P18 -> 4.5507359 | J18: =(C18-SUM($F$2:F18))*100/Q18 -> 1.2239583 | K18: =(B18-F18)*100/P18 -> 2.7164988 | L18: =(C18-SUM($F$2:F18))*100/P18 -> 4.5507359 | M18: =B18*100/O18 -> 3.3874653 | N18: 849841 | O18: =N18+200000 -> 1049841 | P18: 1291000 | Q18: 4800000 | R18: =P18+C18 -> 1358131 | S18: =C18*100/Q18 -> 1.3985625 | T18: =B18*100/Q18 -> 0.74089583
A19: =WORKDAY(A18,1) -> 46169 | B19: =IFERROR(IF(C19<>C18,C19-C18,""),"") -> 16163 | C19: =C18+16163 -> 83294 | D19: =IF(OR(E18="",E19=""),"",E19-E18) -> 594 | E19: =E18+594 -> 14933 | F19: 493 | G19: =IFERROR(VLOOKUP(A19,[1]SUMMERY!$A$2:$G$21,7,FALSE),"") -> 230197.5 | H19: =G19*100/N19 -> 40.54395 | I19: =(C19-SUM($F$2:F19))*100/P19 -> 5.7645236 | J19: =(C19-SUM($F$2:F19))*100/Q19 -> 1.5504167 | K19: =(B19-F19)*100/P19 -> 1.2137878 | L19: =(C19-SUM($F$2:F19))*100/P19 -> 5.7645236 | M19: =B19*100/O19 -> 2.1051802 | N19: =288059.75+279713 -> 567772.75 | O19: =N19+200000 -> 767772.75 | P19: 1291000 | Q19: 4800000 | R19: =P19+C19 -> 1374294 | S19: =C19*100/Q19 -> 1.7352917 | T19: =B19*100/Q19 -> 0.33672917
A20: 46171 | B20: =IFERROR(IF(C20<>C19,C20-C19,""),"") -> 25419 | C20: 108713 | D20: =IF(OR(E19="",E20=""),"",E20-E19) -> 897 | E20: =E19+897 -> 15830 | F20: 493 | G20: =IFERROR(VLOOKUP(A20,[1]SUMMERY!$A$2:$G$21,7,FALSE),"") -> 485000.75 | H20: =G20*100/N20 -> 43.736986 | I20: =(C20-SUM($F$2:F20))*100/P20 -> 7.695275 | J20: =(C20-SUM($F$2:F20))*100/Q20 -> 2.0697083 | K20: =(B20-F20)*100/P20 -> 1.9307514 | L20: =(C20-SUM($F$2:F20))*100/P20 -> 7.695275 | M20: =B20*100/O20 -> 1.9420079 | N20: 1108903 | O20: =N20+200000 -> 1308903 | P20: 1291000 | Q20: 4800000 | R20: =P20+C20 -> 1399713 | S20: =C20*100/Q20 -> 2.2648542 | T20: =B20*100/Q20 -> 0.5295625
A21: =WORKDAY(A20,1) -> 46174 | B21: =IFERROR(IF(C21<>C20,C21-C20,""),"") -> -24392 | C21: =C18+17190 -> 84321 | D21: =IF(OR(E20="",E21=""),"",E21-E20) -> 562 | E21: =E20+562 -> 16392 | F21: 493 | G21: =IFERROR(VLOOKUP(A21,[2]SUMMERY!$A$2:$G$21,7,FALSE),"") -> 594772.75 | H21: =G21*100/N21 -> 41.512668 | I21: =(C21-SUM($F$2:F21))*100/P21 -> 5.7676995 | J21: =(C21-SUM($F$2:F21))*100/Q21 -> 1.5512708 | K21: =(B21-F21)*100/P21 -> -1.9275755 | L21: =(C21-SUM($F$2:F21))*100/P21 -> 5.7676995 | M21: =B21*100/O21 -> -1.4939213 | N21: 1432750 | O21: =N21+200000 -> 1632750 | P21: 1291000 | Q21: 4800000 | R21: =P21+C21 -> 1375321 | S21: =C21*100/Q21 -> 1.7566875 | T21: =B21*100/Q21 -> -0.50816667
A22: =WORKDAY(A21,1) -> 46175 | B22: =IFERROR(IF(C22<>C21,C22-C21,""),"") -> 52803 | C22: 137124 | D22: =IF(OR(E21="",E22=""),"",E22-E21) -> 716 | E22: 17108 | F22: 493 | G22: =IFERROR(VLOOKUP(A22,[2]SUMMERY!$A$2:$G$21,7,FALSE),"") -> 517929.75 | H22: =G22*100/N22 -> 34.512774 | I22: =(C22-SUM($F$2:F22))*100/P22 -> 9.8195972 | J22: =(C22-SUM($F$2:F22))*100/Q22 -> 2.6410625 | K22: =(B22-F22)*100/P22 -> 4.0518978 | L22: =(C22-SUM($F$2:F22))*100/P22 -> 9.8195972 | M22: =B22*100/O22 -> 3.1047986 | N22: =676418+824272 -> 1500690 | O22: =N22+200000 -> 1700690 | P22: 1291000 | Q22: 4800000 | R22: =P22+C22 -> 1428124 | S22: =C22*100/Q22 -> 2.85675 | T22: =B22*100/Q22 -> 1.1000625
A23: =WORKDAY(A22,1) -> 46176 | B23: =IFERROR(IF(C23<>C22,C23-C22,""),"") -> 16344 | C23: 153468 | D23: =IF(OR(E22="",E23=""),"",E23-E22) -> 2112 | E23: 19220 | F23: 493 | G23: =IFERROR(VLOOKUP(A23,[2]SUMMERY!$A$2:$G$21,7,FALSE),"") -> 684086 | H23: =G23*100/N23 -> 38.872476 | I23: =(C23-SUM($F$2:F23))*100/P23 -> 11.047405 | J23: =(C23-SUM($F$2:F23))*100/Q23 -> 2.9712917 | K23: =(B23-F23)*100/P23 -> 1.2278079 | L23: =(C23-SUM($F$2:F23))*100/P23 -> 11.047405 | M23: =B23*100/O23 -> 0.83395371 | N23: 1759821 | O23: =N23+200000 -> 1959821 | P23: 1291000 | Q23: 4800000 | R23: =P23+C23 -> 1444468 | S23: =C23*100/Q23 -> 3.19725 | T23: =B23*100/Q23 -> 0.3405
A24: =WORKDAY(A23,1) -> 46177 | B24: =IFERROR(IF(C24<>C23,C24-C23,""),"") -> 23424 | C24: 176892 | D24: =IF(OR(E23="",E24=""),"",E24-E23) -> 509 | E24: 19729 | F24: 493 | G24: =IFERROR(VLOOKUP(A24,[2]SUMMERY!$A$2:$G$21,7,FALSE),"") -> 626967.25 | H24: =G24*100/N24 -> 38.471565 | I24: =(C24-SUM($F$2:F24))*100/P24 -> 12.823625 | J24: =(C24-SUM($F$2:F24))*100/Q24 -> 3.4490208 | K24: =(B24-F24)*100/P24 -> 1.77622 | L24: =(C24-SUM($F$2:F24))*100/P24 -> 12.823625 | M24: =B24*100/O24 -> 1.2802169 | N24: 1629690 | O24: =N24+200000 -> 1829690 | P24: 1291000 | Q24: 4800000 | R24: =P24+C24 -> 1467892 | S24: =C24*100/Q24 -> 3.68525 | T24: =B24*100/Q24 -> 0.488
A25: =WORKDAY(A24,1) -> 46178 | B25: =IFERROR(IF(C25<>C24,C25-C24,""),"") -> -2660 | C25: =67131+107101 -> 174232 | D25: =IF(OR(E24="",E25=""),"",E25-E24) -> 1100 | E25: =6490+14339 -> 20829 | F25: 493 | G25: =IFERROR(VLOOKUP(A25,[2]SUMMERY!$A$2:$G$21,7,FALSE),"") -> 595429.25 | H25: =G25*100/N25 -> 37.376941 | I25: =(C25-SUM($F$2:F25))*100/P25 -> 12.579396 | J25: =(C25-SUM($F$2:F25))*100/Q25 -> 3.3833333 | K25: =(B25-F25)*100/P25 -> -0.24422928 | L25: =(C25-SUM($F$2:F25))*100/P25 -> 12.579396 | M25: =B25*100/O25 -> -0.14835149 | N25: 1593039 | O25: =N25+200000 -> 1793039 | P25: 1291000 | Q25: 4800000 | R25: =P25+C25 -> 1465232 | S25: =C25*100/Q25 -> 3.6298333 | T25: =B25*100/Q25 -> -0.055416667
A26: =WORKDAY(A25,1) -> 46181 | B26: =IFERROR(IF(C26<>C25,C26-C25,""),"") -> -56253 | C26: =C18+50848 -> 117979 | D26: =IF(OR(E25="",E26=""),"",E26-E25) -> 1585 | E26: =E18+8075 -> 22414 | F26: 493 | G26: =IFERROR(VLOOKUP(A26,[2]SUMMERY!$A$2:$G$21,7,FALSE),"") -> 700758.5 | H26: =G26*100/N26 -> 41.954075 | I26: =(C26-SUM($F$2:F26))*100/P26 -> 8.1838885 | J26: =(C26-SUM($F$2:F26))*100/Q26 -> 2.201125 | K26: =(B26-F26)*100/P26 -> -4.3955074 | L26: =(C26-SUM($F$2:F26))*100/P26 -> 8.1838885 | M26: =B26*100/O26 -> -3.0077009 | N26: 1670299 | O26: =N26+200000 -> 1870299 | P26: 1291000 | Q26: 4800000 | R26: =P26+C26 -> 1408979 | S26: =C26*100/Q26 -> 2.4578958 | T26: =B26*100/Q26 -> -1.1719375
A27: =WORKDAY(A26,1) -> 46182 | B27: =IFERROR(IF(C27<>C26,C27-C26,""),"") -> 59594 | C27: =110442+C18 -> 177573 | D27: =IF(OR(E26="",E27=""),"",E27-E26) -> 1463 | E27: =9538+E18 -> 23877 | F27: 493 | G27: =IFERROR(VLOOKUP(A27,[2]SUMMERY!$A$2:$G$21,7,FALSE),"") -> 471760.25 | H27: =G27*100/N27 -> 37.155838 | I27: =(C27-SUM($F$2:F27))*100/P27 -> 12.761813 | J27: =(C27-SUM($F$2:F27))*100/Q27 -> 3.4323958 | K27: =(B27-F27)*100/P27 -> 4.5779241 | L27: =(C27-SUM($F$2:F27))*100/P27 -> 12.761813 | M27: =B27*100/O27 -> 4.0548963 | N27: 1269680 | O27: =N27+200000 -> 1469680 | P27: 1291000 | Q27: 4800000 | R27: =P27+C27 -> 1468573 | S27: =C27*100/Q27 -> 3.6994375 | T27: =B27*100/Q27 -> 1.2415417
A28: =WORKDAY(A27,1) -> 46183 | B28: =IFERROR(IF(C28<>C27,C28-C27,""),"") -> 3548 | C28: =113990+C18 -> 181121 | D28: =IF(OR(E27="",E28=""),"",E28-E27) -> 1344 | E28: =10882+E18 -> 25221 | F28: 493 | G28: =IFERROR(VLOOKUP(A28,[2]SUMMERY!$A$2:$G$21,7,FALSE),"") | H28: =G28*100/N28 -> #VALUE! | I28: =(C28-SUM($F$2:F28))*100/P28 -> 12.998451 | J28: =(C28-SUM($F$2:F28))*100/Q28 -> 3.4960417 | K28: =(B28-F28)*100/P28 -> 0.23663826 | L28: =(C28-SUM($F$2:F28))*100/P28 -> 12.998451 | M28: =B28*100/O28 -> 0.25094653 | N28: 1213847 | O28: =N28+200000 -> 1413847 | P28: 1291000 | Q28: 4800000 | R28: =P28+C28 -> 1472121 | S28: =C28*100/Q28 -> 3.7733542 | T28: =B28*100/Q28 -> 0.073916667
A29: =WORKDAY(A28,1) -> 46184 | B29: =IFERROR(IF(C29<>C28,C29-C28,""),"") -> 3017 | C29: =117007+C18 -> 184138 | D29: =IF(OR(E28="",E29=""),"",E29-E28) -> 899 | E29: =11781+E18 -> 26120 | F29: 493 | G29: =IFERROR(VLOOKUP(A29,[2]SUMMERY!$A$2:$G$21,7,FALSE),"") | H29: =G29*100/N29 -> #VALUE! | I29: =(C29-SUM($F$2:F29))*100/P29 -> 13.193958 | K29: =(B29-F29)*100/P29 -> 0.19550736 | L29: =(C29-SUM($F$2:F29))*100/P29 -> 13.193958 | M29: =B29*100/O29 -> #DIV/0! | P29: 1291000 | Q29: 4800000 | R29: =P29+C29 -> 1475138 | S29: =C29*100/Q29 -> 3.8362083 | T29: =B29*100/Q29 -> 0.062854167
A30: =WORKDAY(A29,1) -> 46185 | B30: =IFERROR(IF(C30<>C29,C30-C29,""),"") -> -184138 | D30: =IF(OR(E29="",E30=""),"",E30-E29) | F30: 493 | G30: =IFERROR(VLOOKUP(A30,[2]SUMMERY!$A$2:$G$21,7,FALSE),"") | H30: =G30*100/N30 -> #VALUE! | I30: =(C30-SUM($F$2:F30))*100/P30 -> -1.1074361 | K30: =(B30-F30)*100/P30 -> -14.301394 | L30: =(C30-SUM($F$2:F30))*100/P30 -> -1.1074361 | M30: =B30*100/O30 -> #DIV/0! | P30: 1291000 | Q30: 4800000 | R30: =P30+C30 -> 1291000 | S30: =C30*100/Q30 -> 0 | T30: =B30*100/Q30 -> -3.8362083
A31: =WORKDAY(A30,1) -> 46188 | B31: =IFERROR(IF(C31<>C30,C31-C30,""),"") | D31: =IF(OR(E30="",E31=""),"",E31-E30) | F31: 493 | G31: =IFERROR(VLOOKUP(A31,[2]SUMMERY!$A$2:$G$21,7,FALSE),"") | H31: =G31*100/N31 -> #VALUE! | I31: =(C31-SUM($F$2:F31))*100/P31 -> #DIV/0! | K31: =(B31-F31)*100/P31 -> #VALUE! | L31: =(C31-SUM($F$2:F31))*100/P31 -> #DIV/0! | M31: =B31*100/O31 -> #VALUE! | Q31: 4800000 | R31: =P31+C31 -> 0 | S31: =C31*100/Q31 -> 0 | T31: =B31*100/Q31 -> #VALUE!
A32: =WORKDAY(A31,1) -> 46189 | B32: =IFERROR(IF(C32<>C31,C32-C31,""),"") | D32: =IF(OR(E31="",E32=""),"",E32-E31) | F32: 493 | G32: =IFERROR(VLOOKUP(A32,[2]SUMMERY!$A$2:$G$21,7,FALSE),"") | H32: =G32*100/N32 -> #VALUE! | I32: =(C32-SUM($F$2:F32))*100/P32 -> #DIV/0! | K32: =(B32-F32)*100/P32 -> #VALUE! | L32: =(C32-SUM($F$2:F32))*100/P32 -> #DIV/0! | M32: =B32*100/O32 -> #VALUE! | Q32: 4800000 | R32: =P32+C32 -> 0 | S32: =C32*100/Q32 -> 0 | T32: =B32*100/Q32 -> #VALUE!
A33: =WORKDAY(A32,1) -> 46190 | B33: =IFERROR(IF(C33<>C32,C33-C32,""),"") | D33: =IF(OR(E32="",E33=""),"",E33-E32) | F33: 493 | G33: =IFERROR(VLOOKUP(A33,[2]SUMMERY!$A$2:$G$21,7,FALSE),"") | H33: =G33*100/N33 -> #VALUE! | I33: =(C33-SUM($F$2:F33))*100/P33 -> #DIV/0! | K33: =(B33-F33)*100/P33 -> #VALUE! | L33: =(C33-SUM($F$2:F33))*100/P33 -> #DIV/0! | M33: =B33*100/O33 -> #VALUE! | Q33: 4800000 | R33: =P33+C33 -> 0 | S33: =C33*100/Q33 -> 0 | T33: =B33*100/Q33 -> #VALUE!
A34: =WORKDAY(A33,1) -> 46191 | B34: =IFERROR(IF(C34<>C33,C34-C33,""),"") | D34: =IF(OR(E33="",E34=""),"",E34-E33) | F34: 493 | G34: =IFERROR(VLOOKUP(A34,[2]SUMMERY!$A$2:$G$21,7,FALSE),"") | H34: =G34*100/N34 -> #VALUE! | I34: =(C34-SUM($F$2:F34))*100/P34 -> #DIV/0! | K34: =(B34-F34)*100/P34 -> #VALUE! | L34: =(C34-SUM($F$2:F34))*100/P34 -> #DIV/0! | M34: =B34*100/O34 -> #VALUE! | Q34: 4800000 | R34: =P34+C34 -> 0 | S34: =C34*100/Q34 -> 0 | T34: =B34*100/Q34 -> #VALUE!
A35: =WORKDAY(A34,1) -> 46192 | B35: =IFERROR(IF(C35<>C34,C35-C34,""),"") | D35: =IF(OR(E34="",E35=""),"",E35-E34) | F35: 493 | G35: =IFERROR(VLOOKUP(A35,[2]SUMMERY!$A$2:$G$21,7,FALSE),"") | H35: =G35*100/N35 -> #VALUE! | I35: =(C35-SUM($F$2:F35))*100/P35 -> #DIV/0! | K35: =(B35-F35)*100/P35 -> #VALUE! | L35: =(C35-SUM($F$2:F35))*100/P35 -> #DIV/0! | M35: =B35*100/O35 -> #VALUE! | Q35: 4800000 | R35: =P35+C35 -> 0 | S35: =C35*100/Q35 -> 0 | T35: =B35*100/Q35 -> #VALUE!
A36: =WORKDAY(A35,1) -> 46195 | B36: =IFERROR(IF(C36<>C35,C36-C35,""),"") | D36: =IF(OR(E35="",E36=""),"",E36-E35) | F36: 493 | G36: =IFERROR(VLOOKUP(A36,[2]SUMMERY!$A$2:$G$21,7,FALSE),"") | H36: =G36*100/N36 -> #VALUE! | I36: =(C36-SUM($F$2:F36))*100/P36 -> #DIV/0! | K36: =(B36-F36)*100/P36 -> #VALUE! | L36: =(C36-SUM($F$2:F36))*100/P36 -> #DIV/0! | M36: =B36*100/O36 -> #VALUE! | Q36: 4800000 | R36: =P36+C36 -> 0 | S36: =C36*100/Q36 -> 0 | T36: =B36*100/Q36 -> #VALUE!
A37: =WORKDAY(A36,1) -> 46196 | B37: =IFERROR(IF(C37<>C36,C37-C36,""),"") | D37: =IF(OR(E36="",E37=""),"",E37-E36) | F37: 493 | G37: =IFERROR(VLOOKUP(A37,[2]SUMMERY!$A$2:$G$21,7,FALSE),"") | I37: =(C37-SUM($F$2:F37))*100/P37 -> #DIV/0! | K37: =(B37-F37)*100/P37 -> #VALUE! | L37: =(C37-SUM($F$2:F37))*100/P37 -> #DIV/0! | M37: =B37*100/O37 -> #VALUE! | Q37: 4800000 | R37: =P37+C37 -> 0 | S37: =C37*100/Q37 -> 0 | T37: =B37*100/Q37 -> #VALUE!
A38: =A37+1 -> 46197 | B38: =IFERROR(IF(C38<>C37,C38-C37,""),"") | D38: =IF(OR(E37="",E38=""),"",E38-E37) | F38: 493 | G38: =IFERROR(VLOOKUP(A38,[2]SUMMERY!$A$2:$G$21,7,FALSE),"") | I38: =(C38-SUM($F$2:F38))*100/P38 -> #DIV/0! | K38: =(B38-F38)*100/P38 -> #VALUE! | L38: =(C38-SUM($F$2:F38))*100/P38 -> #DIV/0! | M38: =B38*100/O38 -> #VALUE! | Q38: 4800000 | R38: =P38+C38 -> 0 | S38: =C38*100/Q38 -> 0 | T38: =B38*100/Q38 -> #VALUE!
A39: =A38+1 -> 46198 | B39: =IFERROR(IF(C39<>C38,C39-C38,""),"") | D39: =IF(OR(E38="",E39=""),"",E39-E38) | F39: 493 | G39: =IFERROR(VLOOKUP(A39,[2]SUMMERY!$A$2:$G$21,7,FALSE),"") | I39: =(C39-SUM($F$2:F39))*100/P39 -> #DIV/0! | K39: =(B39-F39)*100/P39 -> #VALUE! | L39: =(C39-SUM($F$2:F39))*100/P39 -> #DIV/0! | M39: =B39*100/O39 -> #VALUE! | Q39: 4800000 | S39: =C39*100/Q39 -> 0 | T39: =B39*100/Q39 -> #VALUE!
A40: =A39+1 -> 46199 | B40: =IFERROR(IF(C40<>C39,C40-C39,""),"") | D40: =IF(OR(E39="",E40=""),"",E40-E39) | F40: 493 | G40: =IFERROR(VLOOKUP(A40,[2]SUMMERY!$A$2:$G$21,7,FALSE),"") | I40: =(C40-SUM($F$2:F40))*100/P40 -> #DIV/0! | K40: =(B40-F40)*100/P40 -> #VALUE! | L40: =(C40-SUM($F$2:F40))*100/P40 -> #DIV/0! | Q40: 4800000 | S40: =C40*100/Q40 -> 0 | T40: =B40*100/Q40 -> #VALUE!
A41: =A40+1 -> 46200 | B41: =IFERROR(IF(C41<>C40,C41-C40,""),"") | D41: =IF(OR(E40="",E41=""),"",E41-E40) | F41: 493 | G41: =IFERROR(VLOOKUP(A41,[2]SUMMERY!$A$2:$G$21,7,FALSE),"") | I41: =(C41-SUM($F$2:F41))*100/P41 -> #DIV/0! | K41: =(B41-F41)*100/P41 -> #VALUE! | L41: =(C41-SUM($F$2:F41))*100/P41 -> #DIV/0! | Q41: 4800000 | S41: =C41*100/Q41 -> 0 | T41: =B41*100/Q41 -> #VALUE!
B42: =IFERROR(IF(C42<>C41,C42-C41,""),"") | D42: =IF(OR(E41="",E42=""),"",E42-E41) | F42: 493 | G42: =IFERROR(VLOOKUP(A42,[2]SUMMERY!$A$2:$G$21,7,FALSE),"") | I42: =(C42-SUM($F$2:F42))*100/P42 -> #DIV/0! | K42: =(B42-F42)*100/P42 -> #VALUE! | L42: =(C42-SUM($F$2:F42))*100/P42 -> #DIV/0! | Q42: 4800000 | S42: =C42*100/Q42 -> 0 | T42: =B42*100/Q42 -> #VALUE!
B43: =IFERROR(IF(C43<>C42,C43-C42,""),"") | D43: =IF(OR(E42="",E43=""),"",E43-E42) | F43: 493 | G43: =IFERROR(VLOOKUP(A43,[2]SUMMERY!$A$2:$G$21,7,FALSE),"") | I43: =(C43-SUM($F$2:F43))*100/P43 -> #DIV/0! | K43: =(B43-F43)*100/P43 -> #VALUE! | L43: =(C43-SUM($F$2:F43))*100/P43 -> #DIV/0! | Q43: 4800000 | S43: =C43*100/Q43 -> 0 | T43: =B43*100/Q43 -> #VALUE!
...

Sheet NIFTY VS RCG INTERS 3 X 
A1: DATE | B1: NET MTM | C1: ROI ON DEPOSITE | D1: RUNNING ROI ON DEPOSITE | E1: NIFTY NET CHANGE DAILY | F1: NIFTY NET CONTINUE | G1: DAILY SWING | H1: HIGH | I1: LOW | J1: CLOSE
A2: 46146 | B2: =VLOOKUP(A2,'RCG INTERS '!A2:B61,2,) -> 1238 | C2: =VLOOKUP(A2,'RCG INTERS '!A2:K168,11,) -> 0.057707204 | D2: =VLOOKUP(A2,'RCG INTERS '!A2:I126,9,) -> 0.057707204 | E2: 0 | F2: =E2 -> 0 | G2: =(H2-I2)*100/J2 -> 1.276543 | H2: 24381 | I2: 24072 | J2: 24206
A3: =WORKDAY(A2,1) -> 46147 | B3: =VLOOKUP(A3,'RCG INTERS '!A3:B62,2,) -> 23246 | C3: =VLOOKUP(A3,'RCG INTERS '!A3:K169,11,) -> 1.7624322 | D3: =VLOOKUP(A3,'RCG INTERS '!A3:I127,9,) -> 1.8201394 | E3: =(J3-J2)*100/J2 -> -0.41312071 | F3: =(J2-J3)*100/$J$2 -> 0.41312071 | G3: =(H3-I3)*100/J3 -> 0.87530075 | H3: 24148 | I3: 23937 | J3: 24106
A4: =WORKDAY(A3,1) -> 46148 | B4: =VLOOKUP(A4,'RCG INTERS '!A4:B63,2,) -> -13730 | C4: =VLOOKUP(A4,'RCG INTERS '!A4:K170,11,) -> -1.1017041 | D4: =VLOOKUP(A4,'RCG INTERS '!A4:I128,9,) -> 0.71843532 | E4: =(J4-J3)*100/J3 -> 1.4145856 | F4: =(J4-$J$2)*100/$J$2 -> 0.99562092 | G4: =(H4-I4)*100/J4 -> 1.6934593 | H4: 24470 | I4: 24056 | J4: 24447
A5: =WORKDAY(A4,1) -> 46149 | B5: =VLOOKUP(A5,'RCG INTERS '!A5:B64,2,) -> 45363 | C5: =VLOOKUP(A5,'RCG INTERS '!A5:K171,11,) -> 3.4756003 | D5: =VLOOKUP(A5,'RCG INTERS '!A5:I129,9,) -> 4.1940356 | E5: =(J5-J4)*100/J4 -> -0.26588129 | F5: =(J5-$J$2)*100/$J$2 -> 0.72709246 | G5: =(H5-I5)*100/J5 -> 0.89000082 | H5: 24535 | I5: 24318 | J5: 24382
A6: =WORKDAY(A5,1) -> 46150 | B6: =VLOOKUP(A6,'RCG INTERS '!A6:B65,2,) -> 17156 | C6: =VLOOKUP(A6,'RCG INTERS '!A6:K172,11,) -> 1.2907049 | D6: =VLOOKUP(A6,'RCG INTERS '!A6:I130,9,) -> 5.4847405 | E6: =(J6-J5)*100/J5 -> -0.60700517 | F6: =(J6-$J$2)*100/$J$2 -> 0.1156738 | G6: =(H6-I6)*100/J6 -> 0.55294215 | H6: 24294 | I6: 24160 | J6: 24234
A7: =WORKDAY(A6,1) -> 46153 | B7: =VLOOKUP(A7,'RCG INTERS '!A7:B66,2,) -> -63606 | C7: =VLOOKUP(A7,'RCG INTERS '!A7:K173,11,) -> -4.9650658 | D7: =VLOOKUP(A7,'RCG INTERS '!A7:I131,9,) -> 0.51967467 | E7: =(J7-J6)*100/J6 -> -1.5102748 | F7: =(J7-$J$2)*100/$J$2 -> -1.396348 | G7: =(H7-I7)*100/J7 -> 0.80861404 | H7: 24043 | I7: 23850 | J7: 23868
A8: =WORKDAY(A7,1) -> 46154 | B8: =VLOOKUP(A8,'RCG INTERS '!A8:B67,2,) -> -214994 | C8: =VLOOKUP(A8,'RCG INTERS '!A8:K174,11,) -> -16.691479 | D8: =VLOOKUP(A8,'RCG INTERS '!A8:I132,9,) -> -16.171805 | E8: =(J8-J7)*100/J7 -> -1.8602313 | F8: =(J8-$J$2)*100/$J$2 -> -3.230604 | G8: =(H8-I8)*100/J8 -> 1.6436134 | H8: 23778 | I8: 23393 | J8: 23424
A9: =WORKDAY(A8,1) -> 46155 | B9: =VLOOKUP(A9,'RCG INTERS '!A9:B68,2,) -> 33360 | C9: =VLOOKUP(A9,'RCG INTERS '!A9:K175,11,) -> 2.5458559 | D9: =VLOOKUP(A9,'RCG INTERS '!A9:I133,9,) -> -13.625949 | E9: =(J9-J8)*100/J8 -> 0.16222678 | F9: =(J9-$J$2)*100/$J$2 -> -3.0736181 | G9: =(H9-I9)*100/J9 -> 1.3170233 | H9: 23629 | I9: 23320 | J9: 23462
A10: =WORKDAY(A9,1) -> 46156 | B10: =VLOOKUP(A10,'RCG INTERS '!A10:B69,2,) -> 52179 | C10: =VLOOKUP(A10,'RCG INTERS '!A10:K176,11,) -> 4.0035631 | D10: =VLOOKUP(A10,'RCG INTERS '!A10:I134,9,) -> -9.6223857 | E10: =(J10-J9)*100/J9 -> 1.0144063 | F10: =(J10-$J$2)*100/$J$2 -> -2.0903908 | G10: =(H10-I10)*100/J10 -> 1.5443038 | H10: 23797 | I10: 23431 | J10: 23700
A11: =WORKDAY(A10,1) -> 46157 | B11: =VLOOKUP(A11,'RCG INTERS '!A11:B70,2,) -> 11488 | C11: =VLOOKUP(A11,'RCG INTERS '!A11:K177,11,) -> 0.85166538 | D11: =VLOOKUP(A11,'RCG INTERS '!A11:I135,9,) -> -8.7707204 | E11: =(J11-J10)*100/J10 -> -0.24050633 | F11: =(J11-$J$2)*100/$J$2 -> -2.3258696 | G11: =(H11-I11)*100/J11 -> -0.016918327 | H11: 23854 | I11: 23858 | J11: 23643
A12: =WORKDAY(A11,1) -> 46160 | B12: =VLOOKUP(A12,'RCG INTERS '!A12:B71,2,) -> 6831 | C12: =VLOOKUP(A12,'RCG INTERS '!A12:K178,11,) -> 0.49093726 | D12: =VLOOKUP(A12,'RCG INTERS '!A12:I136,9,) -> -8.2797831 | E12: =(J12-J11)*100/J11 -> 0.063443725 | F12: =(J12-$J$2)*100/$J$2 -> -2.2639015 | G12: =(H12-I12)*100/J12 -> 1.563953 | H12: 23712 | I12: 23342 | J12: 23658
A13: =WORKDAY(A12,1) -> 46161 | B13: =VLOOKUP(A13,'RCG INTERS '!A13:B72,2,) -> 41328 | C13: =VLOOKUP(A13,'RCG INTERS '!A13:K179,11,) -> 3.1630519 | D13: =VLOOKUP(A13,'RCG INTERS '!A13:I137,9,) -> -5.1167312 | E13: =(J13-J12)*100/J12 -> -0.1944374 | F13: =(J13-$J$2)*100/$J$2 -> -2.453937 | G13: =(H13-I13)*100/J13 -> 0.85126207 | H13: 23777 | I13: 23576 | J13: 23612
A14: =WORKDAY(A13,1) -> 46162 | B14: =VLOOKUP(A14,'RCG INTERS '!A14:B73,2,) -> 24067 | C14: =VLOOKUP(A14,'RCG INTERS '!A14:K180,11,) -> 1.8260263 | D14: =VLOOKUP(A14,'RCG INTERS '!A14:I138,9,) -> -3.2907049 | E14: =(J14-J13)*100/J13 -> 0.23716754 | F14: =(J14-$J$2)*100/$J$2 -> -2.2225894 | G14: =(H14-I14)*100/J14 -> 1.3266858 | H14: 23700 | I14: 23386 | J14: 23668
A15: =WORKDAY(A14,1) -> 46163 | B15: =VLOOKUP(A15,'RCG INTERS '!A15:B74,2,) -> 31770 | C15: =VLOOKUP(A15,'RCG INTERS '!A15:K181,11,) -> 2.4226956 | D15: =VLOOKUP(A15,'RCG INTERS '!A15:I139,9,) -> -0.8680093 | E15: =(J15-J14)*100/J14 -> -0.15632922 | F15: =(J15-$J$2)*100/$J$2 -> -2.3754441 | G15: =(H15-I15)*100/J15 -> 1.2145064 | H15: 23837 | I15: 23550 | J15: 23631
... A17: =WORKDAY(A16,1) -> 46167 | B17: =VLOOKUP(A17,'RCG INTERS '!A17:B76,2,) -> 609 | C17: =VLOOKUP(A17,'RCG INTERS '!A17:K183,11,) -> 0.0089852827 | D17: =VLOOKUP(A17,'RCG INTERS '!A17:I141,9,) -> 1.834237 | E17: =(J17-J16)*100/J16 -> 1.3434973 | F17: =(J17-$J$2)*100/$J$2 -> -0.59076262 | G17: =(H17-I17)*100/J17 -> 0.86855338 | H17: 24119 | I17: 23910 | J17: 24063
A18: =WORKDAY(A17,1) -> 46168 | B18: =VLOOKUP(A18,'RCG INTERS '!A18:B77,2,) -> 35563 | C18: =VLOOKUP(A18,'RCG INTERS '!A18:K184,11,) -> 2.7164988 | D18: =VLOOKUP(A18,'RCG INTERS '!A18:I142,9,) -> 4.5507359 | E18: =(J18-J17)*100/J17 -> -0.62336367 | F18: =(J18-$J$2)*100/$J$2 -> -1.2104437 | G18: =(H18-I18)*100/J18 -> 0.85309246 | H18: 24089 | I18: 23885 | J18: 23913 | K18: MAY END
A19: =WORKDAY(A18,1) -> 46169 | B19: =VLOOKUP(A19,'RCG INTERS '!A19:B78,2,) -> 16163 | C19: =VLOOKUP(A19,'RCG INTERS '!A19:K185,11,) -> 1.2137878 | D19: =VLOOKUP(A19,'RCG INTERS '!A19:I143,9,) -> 5.7645236 | E19: =(J19-J18)*100/J18 -> 0.34709154 | F19: =(J19-$J$2)*100/$J$2 -> -0.8675535 | G19: =(H19-I19)*100/J19 -> 0.52092015 | H19: 24045 | I19: 23920 | J19: 23996
A20: 46171 | B20: =VLOOKUP(A20,'RCG INTERS '!A20:B79,2,) -> 25419 | C20: =VLOOKUP(A20,'RCG INTERS '!A20:K186,11,) -> 1.9307514 | D20: =VLOOKUP(A20,'RCG INTERS '!A20:I144,9,) -> 7.695275 | E20: =(J20-J19)*100/J19 -> -1.0335056 | F20: =(J20-$J$2)*100/$J$2 -> -1.8920929 | G20: =(H20-I20)*100/J20 -> 1.4906518 | H20: 24065 | I20: 23711 | J20: 23748
A21: =WORKDAY(A20,1) -> 46174 | B21: =VLOOKUP(A21,'RCG INTERS '!A21:B80,2,) -> -24392 | C21: =VLOOKUP(A21,'RCG INTERS '!A21:K187,11,) -> -1.9275755 | D21: =VLOOKUP(A21,'RCG INTERS '!A21:I145,9,) -> 5.7676995 | E21: =(J21-J20)*100/J20 -> -1.2043119 | F21: =(J21-$J$2)*100/$J$2 -> -3.0736181 | G21: =(H21-I21)*100/J21 -> 1.4619385 | H21: 23779 | I21: 23436 | J21: 23462
A22: =WORKDAY(A21,1) -> 46175 | B22: =VLOOKUP(A22,'RCG INTERS '!A22:B81,2,) -> 52803 | C22: =VLOOKUP(A22,'RCG INTERS '!A22:K188,11,) -> 4.0518978 | D22: =VLOOKUP(A22,'RCG INTERS '!A22:I146,9,) -> 9.8195972 | E22: =(J22-J21)*100/J21 -> 0.60097178 | F22: =(J22-$J$2)*100/$J$2 -> -2.4911179 | G22: =(H22-I22)*100/J22 -> 1.5421768 | H22: 23650 | I22: 23286 | J22: 23603
A23: =WORKDAY(A22,1) -> 46176 | B23: =VLOOKUP(A23,'RCG INTERS '!A23:B82,2,) -> 16344 | C23: =VLOOKUP(A23,'RCG INTERS '!A23:K189,11,) -> 1.2278079 | D23: =VLOOKUP(A23,'RCG INTERS '!A23:I147,9,) -> 11.047405 | E23: =(J23-J22)*100/J22 -> -0.37283396 | F23: =(J23-$J$2)*100/$J$2 -> -2.8546641 | G23: =(H23-I23)*100/J23 -> 1.5649585 | H23: 23580 | I23: 23212 | J23: 23515
A24: =WORKDAY(A23,1) -> 46177 | B24: =VLOOKUP(A24,'RCG INTERS '!A24:B83,2,) -> 23424 | C24: =VLOOKUP(A24,'RCG INTERS '!A24:K190,11,) -> 1.77622 | D24: =VLOOKUP(A24,'RCG INTERS '!A24:I148,9,) -> 12.823625 | E24: =(J24-J23)*100/J23 -> -0.017010419 | F24: =(J24-$J$2)*100/$J$2 -> -2.871189 | G24: =(H24-I24)*100/J24 -> 0.92297223 | H24: 23543 | I24: 23326 | J24: 23511
A25: =WORKDAY(A24,1) -> 46178 | B25: =VLOOKUP(A25,'RCG INTERS '!A25:B84,2,) -> -2660 | C25: =VLOOKUP(A25,'RCG INTERS '!A25:K191,11,) -> -0.24422928 | D25: =VLOOKUP(A25,'RCG INTERS '!A25:I149,9,) -> 12.579396 | E25: =(J25-J24)*100/J24 -> -0.25519969 | F25: =(J25-$J$2)*100/$J$2 -> -3.1190614 | G25: =(H25-I25)*100/J25 -> 0.59272526 | H25: 23590 | I25: 23451 | J25: 23451
A26: =WORKDAY(A25,1) -> 46181 | B26: =VLOOKUP(A26,'RCG INTERS '!A26:B85,2,) -> -56253 | C26: =VLOOKUP(A26,'RCG INTERS '!A26:K192,11,) -> -4.3955074 | D26: =VLOOKUP(A26,'RCG INTERS '!A26:I150,9,) -> 8.1838885 | E26: =(J26-J25)*100/J25 -> -1.1811863 | F26: =(J26-$J$2)*100/$J$2 -> -4.2634058 | G26: =(H26-I26)*100/J26 -> 0.91050315 | H26: 23353 | I26: 23142 | J26: 23174
A27: =WORKDAY(A26,1) -> 46182 | B27: =VLOOKUP(A27,'RCG INTERS '!A27:B86,2,) -> 59594 | C27: =VLOOKUP(A27,'RCG INTERS '!A27:K193,11,) -> 4.5779241 | D27: =VLOOKUP(A27,'RCG INTERS '!A27:I151,9,) -> 12.761813 | E27: =(J27-J26)*100/J26 -> 0.67748339 | F27: =E26+E27 -> -0.50370292 | G27: =(H27-I27)*100/J27 -> 0.87437315 | H27: 23349 | I27: 23145 | J27: 23331
A28: =WORKDAY(A27,1) -> 46183 | B28: =VLOOKUP(A28,'RCG INTERS '!A28:B87,2,) -> 3548 | C28: =VLOOKUP(A28,'RCG INTERS '!A28:K194,11,) -> 0.23663826 | D28: =VLOOKUP(A28,'RCG INTERS '!A28:I152,9,) -> 12.998451 | E28: =(J28-J27)*100/J27 -> -0.390039 | F28: =E27+E28 -> 0.28744438 | G28: =(H28-I28)*100/J28 -> 1.0111876 | H28: 23456 | I28: 23221 | J28: 23240
A29: =WORKDAY(A28,1) -> 46184 | B29: =VLOOKUP(A29,'RCG INTERS '!A29:B88,2,) -> 3017 | C29: =VLOOKUP(A29,'RCG INTERS '!A29:K195,11,) -> 0.19550736 | D29: =VLOOKUP(A29,'RCG INTERS '!A29:I153,9,) -> 13.193958 | E29: =(J29-J28)*100/J28 -> -0.17211704 | F29: =E28+E29 -> -0.56215604 | G29: =(H29-I29)*100/J29 -> 1.112069 | H29: 23363 | I29: 23105 | J29: 23200
A30: =WORKDAY(A29,1) -> 46185 | B30: =VLOOKUP(A30,'RCG INTERS '!A30:B89,2,) -> -184138 | C30: =VLOOKUP(A30,'RCG INTERS '!A30:K196,11,) -> -14.301394 | D30: =VLOOKUP(A30,'RCG INTERS '!A30:I154,9,) -> -1.1074361 | E30: =(J30-J29)*100/J29 -> -100 | F30: =E29+E30 -> -100.17212 | G30: =(H30-I30)*100/J30 -> #DIV/0!
A31: =WORKDAY(A30,1) -> 46188 | B31: =VLOOKUP(A31,'RCG INTERS '!A31:B90,2,) | C31: =VLOOKUP(A31,'RCG INTERS '!A31:K197,11,) -> #VALUE! | D31: =VLOOKUP(A31,'RCG INTERS '!A31:I155,9,) -> #DIV/0! | E31: =(J31-J30)*100/J30 -> #DIV/0! | F31: =E30+E31 -> #DIV/0! | G31: =(H31-I31)*100/J31 -> #DIV/0!
A32: =WORKDAY(A31,1) -> 46189 | B32: =VLOOKUP(A32,'RCG INTERS '!A32:B91,2,) | C32: =VLOOKUP(A32,'RCG INTERS '!A32:K198,11,) -> #VALUE! | D32: =VLOOKUP(A32,'RCG INTERS '!A32:I156,9,) -> #DIV/0! | E32: =(J32-J31)*100/J31 -> #DIV/0! | F32: =E31+E32 -> #DIV/0! | G32: =(H32-I32)*100/J32 -> #DIV/0!
A33: =WORKDAY(A32,1) -> 46190 | B33: =VLOOKUP(A33,'RCG INTERS '!A33:B92,2,) | C33: =VLOOKUP(A33,'RCG INTERS '!A33:K199,11,) -> #VALUE! | D33: =VLOOKUP(A33,'RCG INTERS '!A33:I157,9,) -> #DIV/0! | E33: =(J33-J32)*100/J32 -> #DIV/0! | F33: =E32+E33 -> #DIV/0! | G33: =(H33-I33)*100/J33 -> #DIV/0!
A34: =WORKDAY(A33,1) -> 46191 | B34: =VLOOKUP(A34,'RCG INTERS '!A34:B93,2,) | C34: =VLOOKUP(A34,'RCG INTERS '!A34:K200,11,) -> #VALUE! | D34: =VLOOKUP(A34,'RCG INTERS '!A34:I158,9,) -> #DIV/0! | E34: =(J34-J33)*100/J33 -> #DIV/0! | F34: =E33+E34 -> #DIV/0! | G34: =(H34-I34)*100/J34 -> #DIV/0!
A35: =WORKDAY(A34,1) -> 46192 | B35: =VLOOKUP(A35,'RCG INTERS '!A35:B94,2,) | C35: =VLOOKUP(A35,'RCG INTERS '!A35:K201,11,) -> #VALUE! | D35: =VLOOKUP(A35,'RCG INTERS '!A35:I159,9,) -> #DIV/0! | E35: =(J35-J34)*100/J34 -> #DIV/0! | F35: =E34+E35 -> #DIV/0! | G35: =(H35-I35)*100/J35 -> #DIV/0!
A36: =WORKDAY(A35,1) -> 46195 | B36: =VLOOKUP(A36,'RCG INTERS '!A36:B95,2,) | C36: =VLOOKUP(A36,'RCG INTERS '!A36:K202,11,) -> #VALUE! | D36: =VLOOKUP(A36,'RCG INTERS '!A36:I160,9,) -> #DIV/0! | E36: =(J36-J35)*100/J35 -> #DIV/0! | F36: =E35+E36 -> #DIV/0! | G36: =(H36-I36)*100/J36 -> #DIV/0!
A37: =WORKDAY(A36,1) -> 46196 | B37: =VLOOKUP(A37,'RCG INTERS '!A37:B96,2,) | C37: =VLOOKUP(A37,'RCG INTERS '!A37:K203,11,) -> #VALUE! | D37: =VLOOKUP(A37,'RCG INTERS '!A37:I161,9,) -> #DIV/0! | E37: =(J37-J36)*100/J36 -> #DIV/0! | F37: =E36+E37 -> #DIV/0! | G37: =(H37-I37)*100/J37 -> #DIV/0!
A38: =A37+1 -> 46197 | C38: =VLOOKUP(A38,'RCG INTERS '!A38:K204,11,) -> #VALUE! | D38: =VLOOKUP(A38,'RCG INTERS '!A38:I162,9,) -> #DIV/0! | E38: =(J38-J37)*100/J37 -> #DIV/0! | F38: =E37+E38 -> #DIV/0! | G38: =(H38-I38)*100/J38 -> #DIV/0!
A39: =A38+1 -> 46198 | C39: =VLOOKUP(A39,'RCG INTERS '!A39:K205,11,) -> #VALUE! | D39: =VLOOKUP(A39,'RCG INTERS '!A39:I163,9,) -> #DIV/0! | E39: =(J39-J38)*100/J38 -> #DIV/0! | F39: =E38+E39 -> #DIV/0! | G39: =(H39-I39)*100/J39 -> #DIV/0!
A40: =A39+1 -> 46199 | C40: =VLOOKUP(A40,'RCG INTERS '!A40:K206,11,) -> #VALUE! | D40: =VLOOKUP(A40,'RCG INTERS '!A40:I164,9,) -> #DIV/0! | E40: =(J40-J39)*100/J39 -> #DIV/0! | F40: =E39+E40 -> #DIV/0! | G40: =(H40-I40)*100/J40 -> #DIV/0!
A41: =A40+1 -> 46200 | C41: =VLOOKUP(A41,'RCG INTERS '!A41:K207,11,) -> #VALUE! | D41: =VLOOKUP(A41,'RCG INTERS '!A41:I165,9,) -> #DIV/0! | E41: =(J41-J40)*100/J40 -> #DIV/0! | F41: =E40+E41 -> #DIV/0! | G41: =(H41-I41)*100/J41 -> #DIV/0!
...

Sheet NIFTY VS RCG INTERS NET AMOUNT
A1: DATE | B1: NET MTM | C1: RUNNING ROI | D1: DAY ROI | E1: NIFTY NET CHANGE DAILY | F1: NIFTY NET CONTINUE | G1: DAILY SWING | H1: HIGH | I1: LOW | J1: CLOSE
A2: 46146 | B2: =VLOOKUP(A2,'RCG INTERS '!A2:B61,2,) -> 1238 | C2: =VLOOKUP(A2,'RCG INTERS '!A2:S92,19,) -> 0.025791667 | D2: =VLOOKUP(A2,'RCG INTERS '!A2:T154,20,) -> 0.025791667 | E2: 0 | F2: =E2 -> 0 | G2: =(H2-I2)*100/J2 -> 1.276543 | H2: 24381 | I2: 24072 | J2: 24206
A3: =WORKDAY(A2,1) -> 46147 | B3: =VLOOKUP(A3,'RCG INTERS '!A3:B62,2,) -> 23246 | C3: =VLOOKUP(A3,'RCG INTERS '!A3:S93,19,) -> 0.51008333 | D3: =VLOOKUP(A3,'RCG INTERS '!A3:T155,20,) -> 0.48429167 | E3: =(J3-J2)*100/J2 -> -0.41312071 | F3: =(J2-J3)*100/$J$2 -> 0.41312071 | G3: =(H3-I3)*100/J3 -> 0.87530075 | H3: 24148 | I3: 23937 | J3: 24106
A4: =WORKDAY(A3,1) -> 46148 | B4: =VLOOKUP(A4,'RCG INTERS '!A4:B63,2,) -> -13730 | C4: =VLOOKUP(A4,'RCG INTERS '!A4:S94,19,) -> 0.22404167 | D4: =VLOOKUP(A4,'RCG INTERS '!A4:T156,20,) -> -0.28604167 | E4: =(J4-J3)*100/J3 -> 1.4145856 | F4: =(J4-$J$2)*100/$J$2 -> 0.99562092 | G4: =(H4-I4)*100/J4 -> 1.6934593 | H4: 24470 | I4: 24056 | J4: 24447
A5: =WORKDAY(A4,1) -> 46149 | B5: =VLOOKUP(A5,'RCG INTERS '!A5:B64,2,) -> 45363 | C5: =VLOOKUP(A5,'RCG INTERS '!A5:S95,19,) -> 1.1691042 | D5: =VLOOKUP(A5,'RCG INTERS '!A5:T157,20,) -> 0.9450625 | E5: =(J5-J4)*100/J4 -> -0.26588129 | F5: =(J5-$J$2)*100/$J$2 -> 0.72709246 | G5: =(H5-I5)*100/J5 -> 0.89000082 | H5: 24535 | I5: 24318 | J5: 24382
A6: =WORKDAY(A5,1) -> 46150 | B6: =VLOOKUP(A6,'RCG INTERS '!A6:B65,2,) -> 17156 | C6: =VLOOKUP(A6,'RCG INTERS '!A6:S96,19,) -> 1.5265208 | D6: =VLOOKUP(A6,'RCG INTERS '!A6:T158,20,) -> 0.35741667 | E6: =(J6-J5)*100/J5 -> -0.60700517 | F6: =(J6-$J$2)*100/$J$2 -> 0.1156738 | G6: =(H6-I6)*100/J6 -> 0.55294215 | H6: 24294 | I6: 24160 | J6: 24234
A7: =WORKDAY(A6,1) -> 46153 | B7: =VLOOKUP(A7,'RCG INTERS '!A7:B66,2,) -> -63606 | C7: =VLOOKUP(A7,'RCG INTERS '!A7:S97,19,) -> 0.20139583 | D7: =VLOOKUP(A7,'RCG INTERS '!A7:T159,20,) -> -1.325125 | E7: =(J7-J6)*100/J6 -> -1.5102748 | F7: =(J7-$J$2)*100/$J$2 -> -1.396348 | G7: =(H7-I7)*100/J7 -> 0.80861404 | H7: 24043 | I7: 23850 | J7: 23868
A8: =WORKDAY(A7,1) -> 46154 | B8: =VLOOKUP(A8,'RCG INTERS '!A8:B67,2,) -> -214994 | C8: =VLOOKUP(A8,'RCG INTERS '!A8:S98,19,) -> -4.2776458 | D8: =VLOOKUP(A8,'RCG INTERS '!A8:T160,20,) -> -4.4790417 | E8: =(J8-J7)*100/J7 -> -1.8602313 | F8: =(J8-$J$2)*100/$J$2 -> -3.230604 | G8: =(H8-I8)*100/J8 -> 1.6436134 | H8: 23778 | I8: 23393 | J8: 23424
A9: =WORKDAY(A8,1) -> 46155 | B9: =VLOOKUP(A9,'RCG INTERS '!A9:B68,2,) -> 33360 | C9: =VLOOKUP(A9,'RCG INTERS '!A9:S99,19,) -> -3.5826458 | D9: =VLOOKUP(A9,'RCG INTERS '!A9:T161,20,) -> 0.695 | E9: =(J9-J8)*100/J8 -> 0.16222678 | F9: =(J9-$J$2)*100/$J$2 -> -3.0736181 | G9: =(H9-I9)*100/J9 -> 1.3170233 | H9: 23629 | I9: 23320 | J9: 23462
A10: =WORKDAY(A9,1) -> 46156 | B10: =VLOOKUP(A10,'RCG INTERS '!A10:B69,2,) -> 52179 | C10: =VLOOKUP(A10,'RCG INTERS '!A10:S100,19,) -> -2.4955833 | D10: =VLOOKUP(A10,'RCG INTERS '!A10:T162,20,) -> 1.0870625 | E10: =(J10-J9)*100/J9 -> 1.0144063 | F10: =(J10-$J$2)*100/$J$2 -> -2.0903908 | G10: =(H10-I10)*100/J10 -> 1.5443038 | H10: 23797 | I10: 23431 | J10: 23700
A11: =WORKDAY(A10,1) -> 46157 | B11: =VLOOKUP(A11,'RCG INTERS '!A11:B70,2,) -> 11488 | C11: =VLOOKUP(A11,'RCG INTERS '!A11:S101,19,) -> -2.25625 | D11: =VLOOKUP(A11,'RCG INTERS '!A11:T163,20,) -> 0.23933333 | E11: =(J11-J10)*100/J10 -> -0.24050633 | F11: =(J11-$J$2)*100/$J$2 -> -2.3258696 | G11: =(H11-I11)*100/J11 -> -0.016918327 | H11: 23854 | I11: 23858 | J11: 23643
A12: =WORKDAY(A11,1) -> 46160 | B12: =VLOOKUP(A12,'RCG INTERS '!A12:B71,2,) -> 6831 | C12: =VLOOKUP(A12,'RCG INTERS '!A12:S102,19,) -> -2.1139375 | D12: =VLOOKUP(A12,'RCG INTERS '!A12:T164,20,) -> 0.1423125 | E12: =(J12-J11)*100/J11 -> 0.063443725 | F12: =(J12-$J$2)*100/$J$2 -> -2.2639015 | G12: =(H12-I12)*100/J12 -> 1.563953 | H12: 23712 | I12: 23342 | J12: 23658
A13: =WORKDAY(A12,1) -> 46161 | B13: =VLOOKUP(A13,'RCG INTERS '!A13:B72,2,) -> 41328 | C13: =VLOOKUP(A13,'RCG INTERS '!A13:S103,19,) -> -1.2529375 | D13: =VLOOKUP(A13,'RCG INTERS '!A13:T165,20,) -> 0.861 | E13: =(J13-J12)*100/J12 -> -0.1944374 | F13: =(J13-$J$2)*100/$J$2 -> -2.453937 | G13: =(H13-I13)*100/J13 -> 0.85126207 | H13: 23777 | I13: 23576 | J13: 23612
A14: =WORKDAY(A13,1) -> 46162 | B14: =VLOOKUP(A14,'RCG INTERS '!A14:B73,2,) -> 24067 | C14: =VLOOKUP(A14,'RCG INTERS '!A14:S104,19,) -> -0.75154167 | D14: =VLOOKUP(A14,'RCG INTERS '!A14:T166,20,) -> 0.50139583 | E14: =(J14-J13)*100/J13 -> 0.23716754 | F14: =(J14-$J$2)*100/$J$2 -> -2.2225894 | G14: =(H14-I14)*100/J14 -> 1.3266858 | H14: 23700 | I14: 23386 | J14: 23668
A15: =WORKDAY(A14,1) -> 46163 | B15: =VLOOKUP(A15,'RCG INTERS '!A15:B74,2,) -> 31770 | C15: =VLOOKUP(A15,'RCG INTERS '!A15:S105,19,) -> -0.089666667 | D15: =VLOOKUP(A15,'RCG INTERS '!A15:T167,20,) -> 0.661875 | E15: =(J15-J14)*100/J14 -> -0.15632922 | F15: =(J15-$J$2)*100/$J$2 -> -2.3754441 | G15: =(H15-I15)*100/J15 -> 1.2145064 | H15: 23837 | I15: 23550 | J15: 23631
... A19: =WORKDAY(A18,1) -> 46169 | B19: =VLOOKUP(A19,'RCG INTERS '!A19:B78,2,) -> 16163 | C19: =VLOOKUP(A19,'RCG INTERS '!A19:S109,19,) -> 1.7352917 | D19: =VLOOKUP(A19,'RCG INTERS '!A19:T171,20,) -> 0.33672917 | E19: =(J19-J18)*100/J18 -> 0.34709154 | F19: =(J19-$J$2)*100/$J$2 -> -0.8675535 | G19: =(H19-I19)*100/J19 -> 0.52092015 | H19: 24045 | I19: 23920 | J19: 23996
A20: 46171 | B20: =VLOOKUP(A20,'RCG INTERS '!A20:B79,2,) -> 25419 | C20: =VLOOKUP(A20,'RCG INTERS '!A20:S110,19,) -> 2.2648542 | D20: =VLOOKUP(A20,'RCG INTERS '!A20:T172,20,) -> 0.5295625 | E20: =(J20-J19)*100/J19 -> -1.0335056 | F20: =(J20-$J$2)*100/$J$2 -> -1.8920929 | G20: =(H20-I20)*100/J20 -> 1.4906518 | H20: 24065 | I20: 23711 | J20: 23748
A21: =WORKDAY(A20,1) -> 46174 | B21: =VLOOKUP(A21,'RCG INTERS '!A21:B80,2,) -> -24392 | C21: =VLOOKUP(A21,'RCG INTERS '!A21:S111,19,) -> 1.7566875 | D21: =VLOOKUP(A21,'RCG INTERS '!A21:T173,20,) -> -0.50816667 | E21: =(J21-J20)*100/J20 -> -1.2043119 | F21: =(J21-$J$2)*100/$J$2 -> -3.0736181 | G21: =(H21-I21)*100/J21 -> 1.4619385 | H21: 23779 | I21: 23436 | J21: 23462
A22: =WORKDAY(A21,1) -> 46175 | B22: =VLOOKUP(A22,'RCG INTERS '!A22:B81,2,) -> 52803 | C22: =VLOOKUP(A22,'RCG INTERS '!A22:S112,19,) -> 2.85675 | D22: =VLOOKUP(A22,'RCG INTERS '!A22:T174,20,) -> 1.1000625 | E22: =(J22-J21)*100/J21 -> 0.60097178 | F22: =(J22-$J$2)*100/$J$2 -> -2.4911179 | G22: =(H22-I22)*100/J22 -> 1.5421768 | H22: 23650 | I22: 23286 | J22: 23603
A23: =WORKDAY(A22,1) -> 46176 | B23: =VLOOKUP(A23,'RCG INTERS '!A23:B82,2,) -> 16344 | C23: =VLOOKUP(A23,'RCG INTERS '!A23:S113,19,) -> 3.19725 | D23: =VLOOKUP(A23,'RCG INTERS '!A23:T175,20,) -> 0.3405 | E23: =(J23-J22)*100/J22 -> -0.37283396 | F23: =(J23-$J$2)*100/$J$2 -> -2.8546641 | G23: =(H23-I23)*100/J23 -> 1.5649585 | H23: 23580 | I23: 23212 | J23: 23515
A24: =WORKDAY(A23,1) -> 46177 | B24: =VLOOKUP(A24,'RCG INTERS '!A24:B83,2,) -> 23424 | C24: =VLOOKUP(A24,'RCG INTERS '!A24:S114,19,) -> 3.68525 | D24: =VLOOKUP(A24,'RCG INTERS '!A24:T176,20,) -> 0.488 | E24: =(J24-J23)*100/J23 -> -0.017010419 | F24: =(J24-$J$2)*100/$J$2 -> -2.871189 | G24: =(H24-I24)*100/J24 -> 0.92297223 | H24: 23543 | I24: 23326 | J24: 23511
A25: =WORKDAY(A24,1) -> 46178 | B25: =VLOOKUP(A25,'RCG INTERS '!A25:B84,2,) -> -2660 | C25: =VLOOKUP(A25,'RCG INTERS '!A25:S115,19,) -> 3.6298333 | D25: =VLOOKUP(A25,'RCG INTERS '!A25:T177,20,) -> -0.055416667 | E25: =(J25-J24)*100/J24 -> -0.25519969 | F25: =(J25-$J$2)*100/$J$2 -> -3.1190614 | G25: =(H25-I25)*100/J25 -> 0.59272526 | H25: 23590 | I25: 23451 | J25: 23451
A26: =WORKDAY(A25,1) -> 46181 | B26: =VLOOKUP(A26,'RCG INTERS '!A26:B85,2,) -> -56253 | C26: =VLOOKUP(A26,'RCG INTERS '!A26:S116,19,) -> 2.4578958 | D26: =VLOOKUP(A26,'RCG INTERS '!A26:T178,20,) -> -1.1719375 | E26: =(J26-J25)*100/J25 -> -1.1811863 | F26: =(J26-$J$2)*100/$J$2 -> -4.2634058 | G26: =(H26-I26)*100/J26 -> 0.91050315 | H26: 23353 | I26: 23142 | J26: 23174
A27: =WORKDAY(A26,1) -> 46182 | B27: =VLOOKUP(A27,'RCG INTERS '!A27:B86,2,) -> 59594 | C27: =VLOOKUP(A27,'RCG INTERS '!A27:S117,19,) -> 3.6994375 | D27: =VLOOKUP(A27,'RCG INTERS '!A27:T179,20,) -> 1.2415417 | E27: =(J27-J26)*100/J26 -> 0.67748339 | F27: =(J27-$J$2)*100/$J$2 -> -3.6148062 | G27: =(H27-I27)*100/J27 -> 0.87437315 | H27: 23349 | I27: 23145 | J27: 23331
A28: =WORKDAY(A27,1) -> 46183 | B28: =VLOOKUP(A28,'RCG INTERS '!A28:B87,2,) -> 3548 | C28: =VLOOKUP(A28,'RCG INTERS '!A28:S118,19,) -> 3.7733542 | D28: =VLOOKUP(A28,'RCG INTERS '!A28:T180,20,) -> 0.073916667 | E28: =(J28-J27)*100/J27 -> -100 | F28: =(J28-$J$2)*100/$J$2 -> -100 | G28: =(H28-I28)*100/J28 -> #DIV/0!
A29: =WORKDAY(A28,1) -> 46184 | B29: =VLOOKUP(A29,'RCG INTERS '!A29:B88,2,) -> 3017 | C29: =VLOOKUP(A29,'RCG INTERS '!A29:S119,19,) -> 3.8362083 | D29: =VLOOKUP(A29,'RCG INTERS '!A29:T181,20,) -> 0.062854167 | E29: =(J29-J28)*100/J28 -> #DIV/0! | F29: =(J29-$J$2)*100/$J$2 -> -100 | G29: =(H29-I29)*100/J29 -> #DIV/0!
A30: =WORKDAY(A29,1) -> 46185 | B30: =VLOOKUP(A30,'RCG INTERS '!A30:B89,2,) -> -184138 | C30: =VLOOKUP(A30,'RCG INTERS '!A30:S120,19,) -> 0 | D30: =VLOOKUP(A30,'RCG INTERS '!A30:T182,20,) -> -3.8362083 | E30: =(J30-J29)*100/J29 -> #DIV/0! | F30: =(J30-$J$2)*100/$J$2 -> -100 | G30: =(H30-I30)*100/J30 -> #DIV/0!
A31: =WORKDAY(A30,1) -> 46188 | B31: =VLOOKUP(A31,'RCG INTERS '!A31:B90,2,) | C31: =VLOOKUP(A31,'RCG INTERS '!A31:S121,19,) -> 0 | D31: =VLOOKUP(A31,'RCG INTERS '!A31:T183,20,) -> #VALUE! | E31: =(J31-J30)*100/J30 -> #DIV/0! | F31: =(J31-$J$2)*100/$J$2 -> -100 | G31: =(H31-I31)*100/J31 -> #DIV/0!
A32: =WORKDAY(A31,1) -> 46189 | B32: =VLOOKUP(A32,'RCG INTERS '!A32:B91,2,) | C32: =VLOOKUP(A32,'RCG INTERS '!A32:S122,19,) -> 0 | D32: =VLOOKUP(A32,'RCG INTERS '!A32:T184,20,) -> #VALUE! | E32: =(J32-J31)*100/J31 -> #DIV/0! | F32: =(J32-$J$2)*100/$J$2 -> -100 | G32: =(H32-I32)*100/J32 -> #DIV/0!
A33: =WORKDAY(A32,1) -> 46190 | B33: =VLOOKUP(A33,'RCG INTERS '!A33:B92,2,) | C33: =VLOOKUP(A33,'RCG INTERS '!A33:S123,19,) -> 0 | D33: =VLOOKUP(A33,'RCG INTERS '!A33:T185,20,) -> #VALUE! | E33: =(J33-J32)*100/J32 -> #DIV/0! | F33: =(J33-$J$2)*100/$J$2 -> -100 | G33: =(H33-I33)*100/J33 -> #DIV/0!
A34: =WORKDAY(A33,1) -> 46191 | B34: =VLOOKUP(A34,'RCG INTERS '!A34:B93,2,) | C34: =VLOOKUP(A34,'RCG INTERS '!A34:S124,19,) -> 0 | D34: =VLOOKUP(A34,'RCG INTERS '!A34:T186,20,) -> #VALUE! | E34: =(J34-J33)*100/J33 -> #DIV/0! | F34: =(J34-$J$2)*100/$J$2 -> -100 | G34: =(H34-I34)*100/J34 -> #DIV/0!
A35: =WORKDAY(A34,1) -> 46192 | B35: =VLOOKUP(A35,'RCG INTERS '!A35:B94,2,) | C35: =VLOOKUP(A35,'RCG INTERS '!A35:S125,19,) -> 0 | D35: =VLOOKUP(A35,'RCG INTERS '!A35:T187,20,) -> #VALUE! | E35: =(J35-J34)*100/J34 -> #DIV/0! | F35: =(J35-$J$2)*100/$J$2 -> -100 | G35: =(H35-I35)*100/J35 -> #DIV/0!
A36: =WORKDAY(A35,1) -> 46195 | B36: =VLOOKUP(A36,'RCG INTERS '!A36:B95,2,) | C36: =VLOOKUP(A36,'RCG INTERS '!A36:S126,19,) -> 0 | D36: =VLOOKUP(A36,'RCG INTERS '!A36:T188,20,) -> #VALUE! | E36: =(J36-J35)*100/J35 -> #DIV/0! | F36: =(J36-$J$2)*100/$J$2 -> -100 | G36: =(H36-I36)*100/J36 -> #DIV/0!
A37: =WORKDAY(A36,1) -> 46196 | B37: =VLOOKUP(A37,'RCG INTERS '!A37:B96,2,) | C37: =VLOOKUP(A37,'RCG INTERS '!A37:S127,19,) -> 0 | D37: =VLOOKUP(A37,'RCG INTERS '!A37:T189,20,) -> #VALUE! | E37: =(J37-J36)*100/J36 -> #DIV/0! | F37: =(J37-$J$2)*100/$J$2 -> -100 | G37: =(H37-I37)*100/J37 -> #DIV/0!
A38: =A37+1 -> 46197 | C38: =VLOOKUP(A38,'RCG INTERS '!A38:S128,19,) -> 0 | D38: =VLOOKUP(A38,'RCG INTERS '!A38:T190,20,) -> #VALUE! | E38: =(J38-J37)*100/J37 -> #DIV/0! | F38: =(J38-$J$2)*100/$J$2 -> -100 | G38: =(H38-I38)*100/J38 -> #DIV/0!
A39: =A38+1 -> 46198 | C39: =VLOOKUP(A39,'RCG INTERS '!A39:S129,19,) -> 0 | D39: =VLOOKUP(A39,'RCG INTERS '!A39:T191,20,) -> #VALUE! | E39: =(J39-J38)*100/J38 -> #DIV/0! | F39: =(J39-$J$2)*100/$J$2 -> -100 | G39: =(H39-I39)*100/J39 -> #DIV/0!
A40: =A39+1 -> 46199 | C40: =VLOOKUP(A40,'RCG INTERS '!A40:S130,19,) -> 0 | D40: =VLOOKUP(A40,'RCG INTERS '!A40:T192,20,) -> #VALUE! | E40: =(J40-J39)*100/J39 -> #DIV/0! | F40: =(J40-$J$2)*100/$J$2 -> -100 | G40: =(H40-I40)*100/J40 -> #DIV/0!
A41: =A40+1 -> 46200 | C41: =VLOOKUP(A41,'RCG INTERS '!A41:S131,19,) -> 0 | D41: =VLOOKUP(A41,'RCG INTERS '!A41:T193,20,) -> #VALUE! | E41: =(J41-J40)*100/J40 -> #DIV/0! | F41: =(J41-$J$2)*100/$J$2 -> -100 | G41: =(H41-I41)*100/J41 -> #DIV/0!
C42: =VLOOKUP(A42,'RCG INTERS '!A42:S132,19,) -> #N/A | D42: =VLOOKUP(A42,'RCG INTERS '!A42:T194,20,) -> #N/A | E42: =(J42-J41)*100/J41 -> #DIV/0! | F42: =(J42-$J$2)*100/$J$2 -> -100 | G42: =(H42-I42)*100/J42 -> #DIV/0!
C43: =VLOOKUP(A43,'RCG INTERS '!A43:S133,19,) -> #N/A | D43: =VLOOKUP(A43,'RCG INTERS '!A43:T195,20,) -> #N/A | E43: =(J43-J42)*100/J42 -> #DIV/0! | F43: =(J43-$J$2)*100/$J$2 -> -100 | G43: =(H43-I43)*100/J43 -> #DIV/0!
...
